2025-01-10T11:38:12.6782027Z ##[group]Run pytest tardis --tardis-regression-data=/home/runner/work/tardis/tardis/tardis-regression-data --cov=tardis --cov-report=xml --cov-report=html --cov-append -m "not continuum"
2025-01-10T11:38:12.6783350Z [36;1mpytest tardis --tardis-regression-data=/home/runner/work/tardis/tardis/tardis-regression-data --cov=tardis --cov-report=xml --cov-report=html --cov-append -m "not continuum"[0m
2025-01-10T11:38:12.6810808Z shell: /usr/bin/bash -l {0}
2025-01-10T11:38:12.6811041Z env:
2025-01-10T11:38:12.6811206Z   CACHE_NUMBER: 0
2025-01-10T11:38:12.6811825Z   PYTEST_FLAGS: --tardis-regression-data=/home/runner/work/tardis/tardis/tardis-regression-data --cov=tardis --cov-report=xml --cov-report=html --cov-append
2025-01-10T11:38:12.6812496Z   CODECOV_TOKEN: 
2025-01-10T11:38:12.6812714Z   MAMBA_ROOT_PREFIX: /home/runner/micromamba
2025-01-10T11:38:12.6813009Z   MAMBA_EXE: /home/runner/micromamba-bin/micromamba
2025-01-10T11:38:12.6813368Z   CONDARC: /home/runner/work/_temp/setup-micromamba/.condarc
2025-01-10T11:38:12.6813715Z ##[endgroup]
2025-01-10T11:38:19.6293480Z 
2025-01-10T11:38:19.6294097Z Iterations:                                                                                0/? [00:00<?, ?it/s]
2025-01-10T11:38:19.6294374Z 
2025-01-10T11:38:19.6302636Z Packets:                                                                                   0/? [00:00<?, ?it/s][AImportError while loading conftest '/home/runner/work/tardis/tardis/tardis/conftest.py'.
2025-01-10T11:38:19.8662590Z tardis/conftest.py:11: in <module>
2025-01-10T11:38:19.8663336Z     from tardis.simulation import Simulation
2025-01-10T11:38:19.8663977Z tardis/simulation/__init__.py:5: in <module>
2025-01-10T11:38:19.8664443Z     from tardis.simulation.base import Simulation
2025-01-10T11:38:19.8664930Z tardis/simulation/base.py:14: in <module>
2025-01-10T11:38:19.8665413Z     from tardis.io.model.parse_simulation_state import (
2025-01-10T11:38:19.8665961Z tardis/io/model/parse_simulation_state.py:4: in <module>
2025-01-10T11:38:19.8666688Z     from tardis.model import SimulationState
2025-01-10T11:38:19.8667245Z tardis/model/__init__.py:9: in <module>
2025-01-10T11:38:19.8667760Z     from tardis.model.base import SimulationState
2025-01-10T11:38:19.8668199Z tardis/model/base.py:10: in <module>
2025-01-10T11:38:19.8668698Z     from tardis.io.model.parse_composition_configuration import (
2025-01-10T11:38:19.8669373Z tardis/io/model/parse_composition_configuration.py:1: in <module>
2025-01-10T11:38:19.8670538Z     from tardis.io.model.parse_density_configuration import (
2025-01-10T11:38:19.8671059Z tardis/io/model/parse_density_configuration.py:11: in <module>
2025-01-10T11:38:19.8671530Z     from tardis.io.model.parse_geometry_configuration import (
2025-01-10T11:38:19.8671892Z tardis/io/model/parse_geometry_configuration.py:5: in <module>
2025-01-10T11:38:19.8672257Z     from tardis.io.model.readers.base import read_density_file
2025-01-10T11:38:19.8672580Z tardis/io/model/readers/base.py:9: in <module>
2025-01-10T11:38:19.8672894Z     from tardis.io.model.readers.generic_readers import (
2025-01-10T11:38:19.8673251Z tardis/io/model/readers/generic_readers.py:6: in <module>
2025-01-10T11:38:19.8673547Z     from numpy import recfromtxt
2025-01-10T11:38:19.8674217Z E   ImportError: cannot import name 'recfromtxt' from 'numpy' (/home/runner/micromamba/envs/tardis/lib/python3.12/site-packages/numpy/__init__.py). Did you mean: 'genfromtxt'?
2025-01-10T11:38:20.3794637Z ##[error]Process completed with exit code 4.
