2025-02-03T15:09:01.4929070Z ##[group]Run pytest tardis --tardis-regression-data=/Users/runner/work/tardis/tardis/tardis-regression-data --cov=tardis --cov-report=xml --cov-report=html --cov-append -m " continuum"
2025-02-03T15:09:01.4930120Z [36;1mpytest tardis --tardis-regression-data=/Users/runner/work/tardis/tardis/tardis-regression-data --cov=tardis --cov-report=xml --cov-report=html --cov-append -m " continuum"[0m
2025-02-03T15:09:01.4987530Z shell: /bin/bash -l {0}
2025-02-03T15:09:01.4987740Z env:
2025-02-03T15:09:01.4987900Z   CACHE_NUMBER: 0
2025-02-03T15:09:01.4988400Z   PYTEST_FLAGS: --tardis-regression-data=/Users/runner/work/tardis/tardis/tardis-regression-data --cov=tardis --cov-report=xml --cov-report=html --cov-append
2025-02-03T15:09:01.4988940Z   CODECOV_TOKEN: 
2025-02-03T15:09:01.4989110Z   MAMBA_ROOT_PREFIX: /Users/runner/micromamba
2025-02-03T15:09:01.4989390Z   MAMBA_EXE: /Users/runner/micromamba-bin/micromamba
2025-02-03T15:09:01.4989680Z   CONDARC: /Users/runner/work/_temp/setup-micromamba/.condarc
2025-02-03T15:09:01.4989990Z ##[endgroup]
2025-02-03T15:09:16.1631150Z ============================= test session starts ==============================
2025-02-03T15:09:16.1640420Z platform darwin -- Python 3.12.4, pytest-8.2.2, pluggy-1.5.0
2025-02-03T15:09:16.1641430Z rootdir: /Users/runner/work/tardis/tardis
2025-02-03T15:09:16.1641860Z configfile: pyproject.toml
2025-02-03T15:09:16.1642260Z plugins: cov-5.0.0, html-4.1.1, metadata-3.1.1, doctestplus-1.2.1, anyio-4.4.0
2025-02-03T15:09:16.1642720Z collected 1796 items / 1794 deselected / 2 selected
2025-02-03T15:09:16.1642900Z 
2025-02-03T15:09:17.1628370Z tardis/transport/montecarlo/estimators/tests/test_continuum_property_solver.py E [ 50%]
2025-02-03T15:09:17.1628960Z                                                                          [ 50%]
2025-02-03T15:09:24.4532310Z tardis/transport/montecarlo/tests/test_continuum.py E                    [100%]
2025-02-03T15:09:24.4617470Z 
2025-02-03T15:09:24.4693730Z ==================================== ERRORS ====================================
2025-02-03T15:09:24.4695210Z _________________ ERROR at setup of test_continuum_estimators __________________
2025-02-03T15:09:24.4695720Z 
2025-02-03T15:09:24.4696300Z nlte_atomic_data_fname = PosixPath('/Users/runner/work/tardis/tardis/tardis-regression-data/atom_data/nlte_atom_data/TestNLTE_He_Ti.h5')
2025-02-03T15:09:24.4697010Z 
2025-02-03T15:09:24.4697320Z     @pytest.fixture  # (scope="session")
2025-02-03T15:09:24.4697850Z     def nlte_atomic_dataset(nlte_atomic_data_fname):
2025-02-03T15:09:24.4698420Z         """
2025-02-03T15:09:24.4698880Z         Atomic dataset used for NLTE ionization solver tests.
2025-02-03T15:09:24.4699490Z         """
2025-02-03T15:09:24.4699970Z >       nlte_atomic_data = AtomData.from_hdf(nlte_atomic_data_fname)
2025-02-03T15:09:24.4700440Z 
2025-02-03T15:09:24.4700760Z tardis/tests/fixtures/atom_data.py:73: 
2025-02-03T15:09:24.4701300Z _ _ _ _ _ _ _ _ _ _ _ _ _ _ _ _ _ _ _ _ _ _ _ _ _ _ _ _ _ _ _ _ _ _ _ _ _ _ _ _ 
2025-02-03T15:09:24.4701890Z tardis/io/atom_data/base.py:192: in from_hdf
2025-02-03T15:09:24.4702410Z     with pd.HDFStore(fname, "r") as store:
2025-02-03T15:09:24.4703130Z ../../../micromamba/envs/tardis/lib/python3.12/site-packages/pandas/io/pytables.py:585: in __init__
2025-02-03T15:09:24.4703860Z     self.open(mode=mode, **kwargs)
2025-02-03T15:09:24.4704470Z ../../../micromamba/envs/tardis/lib/python3.12/site-packages/pandas/io/pytables.py:745: in open
2025-02-03T15:09:24.4705200Z     self._handle = tables.open_file(self._path, self._mode, **kwargs)
2025-02-03T15:09:24.4705890Z ../../../micromamba/envs/tardis/lib/python3.12/site-packages/tables/file.py:294: in open_file
2025-02-03T15:09:24.4706610Z     return File(filename, mode, title, root_uep, filters, **kwargs)
2025-02-03T15:09:24.4707280Z ../../../micromamba/envs/tardis/lib/python3.12/site-packages/tables/file.py:744: in __init__
2025-02-03T15:09:24.4713940Z     self._g_new(filename, mode, **params)
2025-02-03T15:09:24.4714330Z _ _ _ _ _ _ _ _ _ _ _ _ _ _ _ _ _ _ _ _ _ _ _ _ _ _ _ _ _ _ _ _ _ _ _ _ _ _ _ _ 
2025-02-03T15:09:24.4715140Z 
2025-02-03T15:09:24.4715260Z >   ???
2025-02-03T15:09:24.4715570Z E   tables.exceptions.HDF5ExtError: HDF5 error back trace
2025-02-03T15:09:24.4715870Z E   
2025-02-03T15:09:24.4716090Z E     File "H5F.c", line 836, in H5Fopen
2025-02-03T15:09:24.4716370Z E       unable to synchronously open file
2025-02-03T15:09:24.4716730Z E     File "H5F.c", line 796, in H5F__open_api_common
2025-02-03T15:09:24.4717030Z E       unable to open file
2025-02-03T15:09:24.4717360Z E     File "H5VLcallback.c", line 3863, in H5VL_file_open
2025-02-03T15:09:24.4717680Z E       open failed
2025-02-03T15:09:24.4717990Z E     File "H5VLcallback.c", line 3675, in H5VL__file_open
2025-02-03T15:09:24.4718270Z E       open failed
2025-02-03T15:09:24.4718610Z E     File "H5VLnative_file.c", line 128, in H5VL__native_file_open
2025-02-03T15:09:24.4718940Z E       unable to open file
2025-02-03T15:09:24.4719220Z E     File "H5Fint.c", line 2018, in H5F_open
2025-02-03T15:09:24.4719440Z E       unable to read superblock
2025-02-03T15:09:24.4719720Z E     File "H5Fsuper.c", line 392, in H5F__super_read
2025-02-03T15:09:24.4720020Z E       file signature not found
2025-02-03T15:09:24.4720310Z E   
2025-02-03T15:09:24.4720510Z E   End of HDF5 error back trace
2025-02-03T15:09:24.4720800Z E   
2025-02-03T15:09:24.4721260Z E   Unable to open/create file '/Users/runner/work/tardis/tardis/tardis-regression-data/atom_data/nlte_atom_data/TestNLTE_He_Ti.h5'
2025-02-03T15:09:24.4721700Z 
2025-02-03T15:09:24.4721840Z tables/hdf5extension.pyx:512: HDF5ExtError
2025-02-03T15:09:24.4722250Z _________________ ERROR at setup of test_montecarlo_continuum __________________
2025-02-03T15:09:24.4722460Z 
2025-02-03T15:09:24.4722840Z nlte_atomic_data_fname = PosixPath('/Users/runner/work/tardis/tardis/tardis-regression-data/atom_data/nlte_atom_data/TestNLTE_He_Ti.h5')
2025-02-03T15:09:24.4723300Z 
2025-02-03T15:09:24.4723450Z     @pytest.fixture  # (scope="session")
2025-02-03T15:09:24.4723810Z     def nlte_atomic_dataset(nlte_atomic_data_fname):
2025-02-03T15:09:24.4724090Z         """
2025-02-03T15:09:24.4724390Z         Atomic dataset used for NLTE ionization solver tests.
2025-02-03T15:09:24.4724690Z         """
2025-02-03T15:09:24.4725000Z >       nlte_atomic_data = AtomData.from_hdf(nlte_atomic_data_fname)
2025-02-03T15:09:24.4725260Z 
2025-02-03T15:09:24.4725340Z tardis/tests/fixtures/atom_data.py:73: 
2025-02-03T15:09:24.4725610Z _ _ _ _ _ _ _ _ _ _ _ _ _ _ _ _ _ _ _ _ _ _ _ _ _ _ _ _ _ _ _ _ _ _ _ _ _ _ _ _ 
2025-02-03T15:09:24.4725860Z tardis/io/atom_data/base.py:192: in from_hdf
2025-02-03T15:09:24.4726190Z     with pd.HDFStore(fname, "r") as store:
2025-02-03T15:09:24.4726610Z ../../../micromamba/envs/tardis/lib/python3.12/site-packages/pandas/io/pytables.py:585: in __init__
2025-02-03T15:09:24.4727090Z     self.open(mode=mode, **kwargs)
2025-02-03T15:09:24.4727480Z ../../../micromamba/envs/tardis/lib/python3.12/site-packages/pandas/io/pytables.py:745: in open
2025-02-03T15:09:24.4727990Z     self._handle = tables.open_file(self._path, self._mode, **kwargs)
2025-02-03T15:09:24.4728500Z ../../../micromamba/envs/tardis/lib/python3.12/site-packages/tables/file.py:294: in open_file
2025-02-03T15:09:24.4728950Z     return File(filename, mode, title, root_uep, filters, **kwargs)
2025-02-03T15:09:24.4729450Z ../../../micromamba/envs/tardis/lib/python3.12/site-packages/tables/file.py:744: in __init__
2025-02-03T15:09:24.4729850Z     self._g_new(filename, mode, **params)
2025-02-03T15:09:24.4730210Z _ _ _ _ _ _ _ _ _ _ _ _ _ _ _ _ _ _ _ _ _ _ _ _ _ _ _ _ _ _ _ _ _ _ _ _ _ _ _ _ 
2025-02-03T15:09:24.4730370Z 
2025-02-03T15:09:24.4730480Z >   ???
2025-02-03T15:09:24.4730790Z E   tables.exceptions.HDF5ExtError: HDF5 error back trace
2025-02-03T15:09:24.4731080Z E   
2025-02-03T15:09:24.4731340Z E     File "H5F.c", line 836, in H5Fopen
2025-02-03T15:09:24.4731890Z E       unable to synchronously open file
2025-02-03T15:09:24.4732240Z E     File "H5F.c", line 796, in H5F__open_api_common
2025-02-03T15:09:24.4732780Z E       unable to open file
2025-02-03T15:09:24.4733110Z E     File "H5VLcallback.c", line 3863, in H5VL_file_open
2025-02-03T15:09:24.4733390Z E       open failed
2025-02-03T15:09:24.4733710Z E     File "H5VLcallback.c", line 3675, in H5VL__file_open
2025-02-03T15:09:24.4734000Z E       open failed
2025-02-03T15:09:24.4734940Z E     File "H5VLnative_file.c", line 128, in H5VL__native_file_open
2025-02-03T15:09:24.4735280Z E       unable to open file
2025-02-03T15:09:24.4735650Z E     File "H5Fint.c", line 2018, in H5F_open
2025-02-03T15:09:24.4735890Z E       unable to read superblock
2025-02-03T15:09:24.4736250Z E     File "H5Fsuper.c", line 392, in H5F__super_read
2025-02-03T15:09:24.4736480Z E       file signature not found
2025-02-03T15:09:24.4736700Z E   
2025-02-03T15:09:24.4736960Z E   End of HDF5 error back trace
2025-02-03T15:09:24.4737210Z E   
2025-02-03T15:09:24.4737720Z E   Unable to open/create file '/Users/runner/work/tardis/tardis/tardis-regression-data/atom_data/nlte_atom_data/TestNLTE_He_Ti.h5'
2025-02-03T15:09:24.4738110Z 
2025-02-03T15:09:24.4738240Z tables/hdf5extension.pyx:512: HDF5ExtError
2025-02-03T15:09:24.4738580Z =============================== warnings summary ===============================
2025-02-03T15:09:24.4738880Z tardis/io/configuration/config_validator.py:6
2025-02-03T15:09:24.4739250Z tardis/io/configuration/config_validator.py:6
2025-02-03T15:09:24.4739720Z   /Users/runner/work/tardis/tardis/tardis/io/configuration/config_validator.py:6: DeprecationWarning:
2025-02-03T15:09:24.4740170Z   
2025-02-03T15:09:24.4741240Z   jsonschema.RefResolver is deprecated as of v4.18.0, in favor of the https://github.com/python-jsonschema/referencing library, which provides more compliant referencing behavior as well as more flexible APIs for customization. A future release will remove RefResolver. Please file a feature request (on referencing) if you are missing an API for the kind of customization you need.
2025-02-03T15:09:24.4742500Z 
2025-02-03T15:09:24.4742730Z ../../../micromamba/envs/tardis/lib/python3.12/site-packages/jupyter_client/connect.py:22
2025-02-03T15:09:24.4743290Z   /Users/runner/micromamba/envs/tardis/lib/python3.12/site-packages/jupyter_client/connect.py:22: DeprecationWarning:
2025-02-03T15:09:24.4743800Z   
2025-02-03T15:09:24.4744050Z   Jupyter is migrating its paths to use standard platformdirs
2025-02-03T15:09:24.4744400Z   given by the platformdirs library.  To remove this warning and
2025-02-03T15:09:24.4744740Z   see the appropriate new directories, set the environment variable
2025-02-03T15:09:24.4745080Z   `JUPYTER_PLATFORM_DIRS=1` and then run `jupyter --paths`.
2025-02-03T15:09:24.4745410Z   The use of platformdirs will be the default in `jupyter_core` v6
2025-02-03T15:09:24.4745600Z 
2025-02-03T15:09:24.4745770Z -- Docs: https://docs.pytest.org/en/stable/how-to/capture-warnings.html
2025-02-03T15:09:24.4746010Z 
2025-02-03T15:09:24.4746150Z ---------- coverage: platform darwin, python 3.12.4-final-0 ----------
2025-02-03T15:09:24.4746450Z Coverage HTML written to dir coverage_html_report
2025-02-03T15:09:24.4746730Z Coverage XML written to file coverage.xml
2025-02-03T15:09:24.4746880Z 
2025-02-03T15:09:24.4746980Z =========================== short test summary info ============================
2025-02-03T15:09:24.4751820Z ERROR tardis/transport/montecarlo/estimators/tests/test_continuum_property_solver.py::test_continuum_estimators - tables.exceptions.HDF5ExtError: HDF5 error back trace
2025-02-03T15:09:24.4752390Z 
2025-02-03T15:09:24.4752460Z   File "H5F.c", line 836, in H5Fopen
2025-02-03T15:09:24.4752800Z     unable to synchronously open file
2025-02-03T15:09:24.4753090Z   File "H5F.c", line 796, in H5F__open_api_common
2025-02-03T15:09:24.4753450Z     unable to open file
2025-02-03T15:09:24.4753730Z   File "H5VLcallback.c", line 3863, in H5VL_file_open
2025-02-03T15:09:24.4754520Z     open failed
2025-02-03T15:09:24.4754770Z   File "H5VLcallback.c", line 3675, in H5VL__file_open
2025-02-03T15:09:24.4755180Z     open failed
2025-02-03T15:09:24.4755500Z   File "H5VLnative_file.c", line 128, in H5VL__native_file_open
2025-02-03T15:09:24.4756470Z     unable to open file
2025-02-03T15:09:24.4756830Z   File "H5Fint.c", line 2018, in H5F_open
2025-02-03T15:09:24.4757120Z     unable to read superblock
2025-02-03T15:09:24.4757440Z   File "H5Fsuper.c", line 392, in H5F__super_read
2025-02-03T15:09:24.4757740Z     file signature not found
2025-02-03T15:09:24.4757920Z 
2025-02-03T15:09:24.4758050Z End of HDF5 error back trace
2025-02-03T15:09:24.4758170Z 
2025-02-03T15:09:24.4758550Z Unable to open/create file '/Users/runner/work/tardis/tardis/tardis-regression-data/atom_data/nlte_atom_data/TestNLTE_He_Ti.h5'
2025-02-03T15:09:24.4759410Z ERROR tardis/transport/montecarlo/tests/test_continuum.py::test_montecarlo_continuum - tables.exceptions.HDF5ExtError: HDF5 error back trace
2025-02-03T15:09:24.4759890Z 
2025-02-03T15:09:24.4759970Z   File "H5F.c", line 836, in H5Fopen
2025-02-03T15:09:24.4760300Z     unable to synchronously open file
2025-02-03T15:09:24.4760610Z   File "H5F.c", line 796, in H5F__open_api_common
2025-02-03T15:09:24.4760980Z     unable to open file
2025-02-03T15:09:24.4761250Z   File "H5VLcallback.c", line 3863, in H5VL_file_open
2025-02-03T15:09:24.4761590Z     open failed
2025-02-03T15:09:24.4761910Z   File "H5VLcallback.c", line 3675, in H5VL__file_open
2025-02-03T15:09:24.4762200Z     open failed
2025-02-03T15:09:24.4762520Z   File "H5VLnative_file.c", line 128, in H5VL__native_file_open
2025-02-03T15:09:24.4762830Z     unable to open file
2025-02-03T15:09:24.4763130Z   File "H5Fint.c", line 2018, in H5F_open
2025-02-03T15:09:24.4763400Z     unable to read superblock
2025-02-03T15:09:24.4763740Z   File "H5Fsuper.c", line 392, in H5F__super_read
2025-02-03T15:09:24.4763990Z     file signature not found
2025-02-03T15:09:24.4764100Z 
2025-02-03T15:09:24.4764220Z End of HDF5 error back trace
2025-02-03T15:09:24.4764400Z 
2025-02-03T15:09:24.4764740Z Unable to open/create file '/Users/runner/work/tardis/tardis/tardis-regression-data/atom_data/nlte_atom_data/TestNLTE_He_Ti.h5'
2025-02-03T15:09:24.4765250Z ================ 1794 deselected, 3 warnings, 2 errors in 9.81s ================
2025-02-03T15:09:25.2440230Z ##[error]Process completed with exit code 1.
