2025-01-10T12:22:36.9425420Z ##[group]Run pytest tardis --tardis-regression-data=/Users/runner/work/tardis/tardis/tardis-regression-data --cov=tardis --cov-report=xml --cov-report=html --cov-append -m "not continuum"
2025-01-10T12:22:36.9426410Z [36;1mpytest tardis --tardis-regression-data=/Users/runner/work/tardis/tardis/tardis-regression-data --cov=tardis --cov-report=xml --cov-report=html --cov-append -m "not continuum"[0m
2025-01-10T12:22:36.9478580Z shell: /bin/bash -l {0}
2025-01-10T12:22:36.9478780Z env:
2025-01-10T12:22:36.9478920Z   CACHE_NUMBER: 0
2025-01-10T12:22:36.9479480Z   PYTEST_FLAGS: --tardis-regression-data=/Users/runner/work/tardis/tardis/tardis-regression-data --cov=tardis --cov-report=xml --cov-report=html --cov-append
2025-01-10T12:22:36.9479980Z   CODECOV_TOKEN: 
2025-01-10T12:22:36.9480170Z   MAMBA_ROOT_PREFIX: /Users/runner/micromamba
2025-01-10T12:22:36.9480430Z   MAMBA_EXE: /Users/runner/micromamba-bin/micromamba
2025-01-10T12:22:36.9480710Z   CONDARC: /Users/runner/work/_temp/setup-micromamba/.condarc
2025-01-10T12:22:36.9481030Z ##[endgroup]
2025-01-10T12:22:46.0399160Z 
2025-01-10T12:22:46.0399760Z Iterations:                                                                                0/? [00:00<?, ?it/s]
2025-01-10T12:22:46.0400170Z 
2025-01-10T12:22:46.0404750Z Packets:                                                                                   0/? [00:00<?, ?it/s][AImportError while loading conftest '/Users/runner/work/tardis/tardis/tardis/conftest.py'.
2025-01-10T12:22:46.2202160Z tardis/conftest.py:11: in <module>
2025-01-10T12:22:46.2202590Z     from tardis.simulation import Simulation
2025-01-10T12:22:46.2202840Z tardis/simulation/__init__.py:5: in <module>
2025-01-10T12:22:46.2203090Z     from tardis.simulation.base import Simulation
2025-01-10T12:22:46.2203390Z tardis/simulation/base.py:14: in <module>
2025-01-10T12:22:46.2203720Z     from tardis.io.model.parse_simulation_state import (
2025-01-10T12:22:46.2204000Z tardis/io/model/parse_simulation_state.py:4: in <module>
2025-01-10T12:22:46.2204300Z     from tardis.model import SimulationState
2025-01-10T12:22:46.2204530Z tardis/model/__init__.py:9: in <module>
2025-01-10T12:22:46.2204750Z     from tardis.model.base import SimulationState
2025-01-10T12:22:46.2204990Z tardis/model/base.py:10: in <module>
2025-01-10T12:22:46.2205240Z     from tardis.io.model.parse_composition_configuration import (
2025-01-10T12:22:46.2205630Z tardis/io/model/parse_composition_configuration.py:1: in <module>
2025-01-10T12:22:46.2206030Z     from tardis.io.model.parse_density_configuration import (
2025-01-10T12:22:46.2206350Z tardis/io/model/parse_density_configuration.py:11: in <module>
2025-01-10T12:22:46.2206660Z     from tardis.io.model.parse_geometry_configuration import (
2025-01-10T12:22:46.2206970Z tardis/io/model/parse_geometry_configuration.py:5: in <module>
2025-01-10T12:22:46.2207300Z     from tardis.io.model.readers.base import read_density_file
2025-01-10T12:22:46.2207560Z tardis/io/model/readers/base.py:9: in <module>
2025-01-10T12:22:46.2207830Z     from tardis.io.model.readers.generic_readers import (
2025-01-10T12:22:46.2208120Z tardis/io/model/readers/generic_readers.py:6: in <module>
2025-01-10T12:22:46.2208360Z     from numpy import recfromtxt
2025-01-10T12:22:46.2208920Z E   ImportError: cannot import name 'recfromtxt' from 'numpy' (/Users/runner/micromamba/envs/tardis/lib/python3.12/site-packages/numpy/__init__.py). Did you mean: 'genfromtxt'?
2025-01-10T12:22:46.6209800Z ##[error]Process completed with exit code 4.
