2025-02-17T19:44:04.3730829Z ##[group]Run pytest tardis --tardis-regression-data=/home/runner/work/tardis/tardis/tardis-regression-data --cov=tardis --cov-report=xml --cov-report=html --cov-append -m " continuum"
2025-02-17T19:44:04.3732108Z [36;1mpytest tardis --tardis-regression-data=/home/runner/work/tardis/tardis/tardis-regression-data --cov=tardis --cov-report=xml --cov-report=html --cov-append -m " continuum"[0m
2025-02-17T19:44:04.3786746Z shell: /usr/bin/bash -l {0}
2025-02-17T19:44:04.3786989Z env:
2025-02-17T19:44:04.3787179Z   CACHE_NUMBER: 0
2025-02-17T19:44:04.3787790Z   PYTEST_FLAGS: --tardis-regression-data=/home/runner/work/tardis/tardis/tardis-regression-data --cov=tardis --cov-report=xml --cov-report=html --cov-append
2025-02-17T19:44:04.3788432Z   CODECOV_TOKEN: 
2025-02-17T19:44:04.3788649Z   MAMBA_ROOT_PREFIX: /home/runner/micromamba
2025-02-17T19:44:04.3788956Z   MAMBA_EXE: /home/runner/micromamba-bin/micromamba
2025-02-17T19:44:04.3789301Z   CONDARC: /home/runner/work/_temp/setup-micromamba/.condarc
2025-02-17T19:44:04.3789632Z ##[endgroup]
2025-02-17T19:44:12.7289188Z ============================= test session starts ==============================
2025-02-17T19:44:12.7290085Z platform linux -- Python 3.12.4, pytest-8.2.2, pluggy-1.5.0
2025-02-17T19:44:12.7290794Z rootdir: /home/runner/work/tardis/tardis
2025-02-17T19:44:12.7291364Z configfile: pyproject.toml
2025-02-17T19:44:12.7292074Z plugins: metadata-3.1.1, anyio-4.4.0, doctestplus-1.2.1, cov-5.0.0, html-4.1.1
2025-02-17T19:44:12.7292947Z collected 1796 items / 1794 deselected / 2 selected
2025-02-17T19:44:12.7293393Z 
2025-02-17T19:44:14.5927547Z tardis/transport/montecarlo/estimators/tests/test_continuum_property_solver.py E [ 50%]
2025-02-17T19:44:14.5929295Z                                                                          [ 50%]
2025-02-17T19:44:21.7709969Z tardis/transport/montecarlo/tests/test_continuum.py E                    [100%]
2025-02-17T19:44:21.7710540Z 
2025-02-17T19:44:21.7710727Z ==================================== ERRORS ====================================
2025-02-17T19:44:21.7711360Z _________________ ERROR at setup of test_continuum_estimators __________________
2025-02-17T19:44:21.7711805Z 
2025-02-17T19:44:21.7712497Z nlte_atomic_data_fname = PosixPath('/home/runner/work/tardis/tardis/tardis-regression-data/atom_data/nlte_atom_data/TestNLTE_He_Ti.h5')
2025-02-17T19:44:21.7713362Z 
2025-02-17T19:44:21.7713523Z     @pytest.fixture  # (scope="session")
2025-02-17T19:44:21.7714260Z     def nlte_atomic_dataset(nlte_atomic_data_fname):
2025-02-17T19:44:21.7715021Z         """
2025-02-17T19:44:21.7715324Z         Atomic dataset used for NLTE ionization solver tests.
2025-02-17T19:44:21.7715654Z         """
2025-02-17T19:44:21.7715927Z >       nlte_atomic_data = AtomData.from_hdf(nlte_atomic_data_fname)
2025-02-17T19:44:21.7716195Z 
2025-02-17T19:44:21.7716311Z tardis/tests/fixtures/atom_data.py:73: 
2025-02-17T19:44:21.7716640Z _ _ _ _ _ _ _ _ _ _ _ _ _ _ _ _ _ _ _ _ _ _ _ _ _ _ _ _ _ _ _ _ _ _ _ _ _ _ _ _ 
2025-02-17T19:44:21.7716986Z tardis/io/atom_data/base.py:192: in from_hdf
2025-02-17T19:44:21.7717315Z     with pd.HDFStore(fname, "r") as store:
2025-02-17T19:44:21.7717831Z ../../../micromamba/envs/tardis/lib/python3.12/site-packages/pandas/io/pytables.py:585: in __init__
2025-02-17T19:44:21.7718335Z     self.open(mode=mode, **kwargs)
2025-02-17T19:44:21.7718788Z ../../../micromamba/envs/tardis/lib/python3.12/site-packages/pandas/io/pytables.py:745: in open
2025-02-17T19:44:21.7719342Z     self._handle = tables.open_file(self._path, self._mode, **kwargs)
2025-02-17T19:44:21.7719891Z ../../../micromamba/envs/tardis/lib/python3.12/site-packages/tables/file.py:294: in open_file
2025-02-17T19:44:21.7720434Z     return File(filename, mode, title, root_uep, filters, **kwargs)
2025-02-17T19:44:21.7720971Z ../../../micromamba/envs/tardis/lib/python3.12/site-packages/tables/file.py:744: in __init__
2025-02-17T19:44:21.7721442Z     self._g_new(filename, mode, **params)
2025-02-17T19:44:21.7721771Z _ _ _ _ _ _ _ _ _ _ _ _ _ _ _ _ _ _ _ _ _ _ _ _ _ _ _ _ _ _ _ _ _ _ _ _ _ _ _ _ 
2025-02-17T19:44:21.7722211Z 
2025-02-17T19:44:21.7722297Z >   ???
2025-02-17T19:44:21.7722561Z E   tables.exceptions.HDF5ExtError: HDF5 error back trace
2025-02-17T19:44:21.7722929Z E   
2025-02-17T19:44:21.7723131Z E     File "H5F.c", line 836, in H5Fopen
2025-02-17T19:44:21.7723429Z E       unable to synchronously open file
2025-02-17T19:44:21.7723954Z E     File "H5F.c", line 796, in H5F__open_api_common
2025-02-17T19:44:21.7724275Z E       unable to open file
2025-02-17T19:44:21.7724565Z E     File "H5VLcallback.c", line 3863, in H5VL_file_open
2025-02-17T19:44:21.7724874Z E       open failed
2025-02-17T19:44:21.7725138Z E     File "H5VLcallback.c", line 3675, in H5VL__file_open
2025-02-17T19:44:21.7725455Z E       open failed
2025-02-17T19:44:21.7725738Z E     File "H5VLnative_file.c", line 128, in H5VL__native_file_open
2025-02-17T19:44:21.7726076Z E       unable to open file
2025-02-17T19:44:21.7726301Z E     File "H5Fint.c", line 2018, in H5F_open
2025-02-17T19:44:21.7726563Z E       unable to read superblock
2025-02-17T19:44:21.7726824Z E     File "H5Fsuper.c", line 392, in H5F__super_read
2025-02-17T19:44:21.7727096Z E       file signature not found
2025-02-17T19:44:21.7727312Z E   
2025-02-17T19:44:21.7727483Z E   End of HDF5 error back trace
2025-02-17T19:44:21.7727695Z E   
2025-02-17T19:44:21.7728169Z E   Unable to open/create file '/home/runner/work/tardis/tardis/tardis-regression-data/atom_data/nlte_atom_data/TestNLTE_He_Ti.h5'
2025-02-17T19:44:21.7728628Z 
2025-02-17T19:44:21.7728728Z tables/hdf5extension.pyx:512: HDF5ExtError
2025-02-17T19:44:21.7729066Z _________________ ERROR at setup of test_montecarlo_continuum __________________
2025-02-17T19:44:21.7729316Z 
2025-02-17T19:44:21.7729719Z nlte_atomic_data_fname = PosixPath('/home/runner/work/tardis/tardis/tardis-regression-data/atom_data/nlte_atom_data/TestNLTE_He_Ti.h5')
2025-02-17T19:44:21.7730200Z 
2025-02-17T19:44:21.7730293Z     @pytest.fixture  # (scope="session")
2025-02-17T19:44:21.7730584Z     def nlte_atomic_dataset(nlte_atomic_data_fname):
2025-02-17T19:44:21.7730854Z         """
2025-02-17T19:44:21.7731092Z         Atomic dataset used for NLTE ionization solver tests.
2025-02-17T19:44:21.7731370Z         """
2025-02-17T19:44:21.7731617Z >       nlte_atomic_data = AtomData.from_hdf(nlte_atomic_data_fname)
2025-02-17T19:44:21.7731845Z 
2025-02-17T19:44:21.7731946Z tardis/tests/fixtures/atom_data.py:73: 
2025-02-17T19:44:21.7732234Z _ _ _ _ _ _ _ _ _ _ _ _ _ _ _ _ _ _ _ _ _ _ _ _ _ _ _ _ _ _ _ _ _ _ _ _ _ _ _ _ 
2025-02-17T19:44:21.7732679Z tardis/io/atom_data/base.py:192: in from_hdf
2025-02-17T19:44:21.7732952Z     with pd.HDFStore(fname, "r") as store:
2025-02-17T19:44:21.7733386Z ../../../micromamba/envs/tardis/lib/python3.12/site-packages/pandas/io/pytables.py:585: in __init__
2025-02-17T19:44:21.7734055Z     self.open(mode=mode, **kwargs)
2025-02-17T19:44:21.7734472Z ../../../micromamba/envs/tardis/lib/python3.12/site-packages/pandas/io/pytables.py:745: in open
2025-02-17T19:44:21.7734967Z     self._handle = tables.open_file(self._path, self._mode, **kwargs)
2025-02-17T19:44:21.7735462Z ../../../micromamba/envs/tardis/lib/python3.12/site-packages/tables/file.py:294: in open_file
2025-02-17T19:44:21.7735942Z     return File(filename, mode, title, root_uep, filters, **kwargs)
2025-02-17T19:44:21.7736419Z ../../../micromamba/envs/tardis/lib/python3.12/site-packages/tables/file.py:744: in __init__
2025-02-17T19:44:21.7736834Z     self._g_new(filename, mode, **params)
2025-02-17T19:44:21.7737122Z _ _ _ _ _ _ _ _ _ _ _ _ _ _ _ _ _ _ _ _ _ _ _ _ _ _ _ _ _ _ _ _ _ _ _ _ _ _ _ _ 
2025-02-17T19:44:21.7737319Z 
2025-02-17T19:44:21.7737393Z >   ???
2025-02-17T19:44:21.7737622Z E   tables.exceptions.HDF5ExtError: HDF5 error back trace
2025-02-17T19:44:21.7737911Z E   
2025-02-17T19:44:21.7738090Z E     File "H5F.c", line 836, in H5Fopen
2025-02-17T19:44:21.7738352Z E       unable to synchronously open file
2025-02-17T19:44:21.7738638Z E     File "H5F.c", line 796, in H5F__open_api_common
2025-02-17T19:44:21.7738913Z E       unable to open file
2025-02-17T19:44:21.7739315Z E     File "H5VLcallback.c", line 3863, in H5VL_file_open
2025-02-17T19:44:21.7739585Z E       open failed
2025-02-17T19:44:21.7739813Z E     File "H5VLcallback.c", line 3675, in H5VL__file_open
2025-02-17T19:44:21.7740088Z E       open failed
2025-02-17T19:44:21.7740345Z E     File "H5VLnative_file.c", line 128, in H5VL__native_file_open
2025-02-17T19:44:21.7740651Z E       unable to open file
2025-02-17T19:44:21.7740887Z E     File "H5Fint.c", line 2018, in H5F_open
2025-02-17T19:44:21.7741146Z E       unable to read superblock
2025-02-17T19:44:21.7741408Z E     File "H5Fsuper.c", line 392, in H5F__super_read
2025-02-17T19:44:21.7741682Z E       file signature not found
2025-02-17T19:44:21.7741895Z E   
2025-02-17T19:44:21.7742064Z E   End of HDF5 error back trace
2025-02-17T19:44:21.7742280Z E   
2025-02-17T19:44:21.7742749Z E   Unable to open/create file '/home/runner/work/tardis/tardis/tardis-regression-data/atom_data/nlte_atom_data/TestNLTE_He_Ti.h5'
2025-02-17T19:44:21.7743210Z 
2025-02-17T19:44:21.7743317Z tables/hdf5extension.pyx:512: HDF5ExtError
2025-02-17T19:44:21.7743618Z =============================== warnings summary ===============================
2025-02-17T19:44:21.7744149Z tardis/io/configuration/config_validator.py:6
2025-02-17T19:44:21.7744451Z tardis/io/configuration/config_validator.py:6
2025-02-17T19:44:21.7744943Z   /home/runner/work/tardis/tardis/tardis/io/configuration/config_validator.py:6: DeprecationWarning:
2025-02-17T19:44:21.7745409Z   
2025-02-17T19:44:21.7746618Z   jsonschema.RefResolver is deprecated as of v4.18.0, in favor of the https://github.com/python-jsonschema/referencing library, which provides more compliant referencing behavior as well as more flexible APIs for customization. A future release will remove RefResolver. Please file a feature request (on referencing) if you are missing an API for the kind of customization you need.
2025-02-17T19:44:21.7747821Z 
2025-02-17T19:44:21.7748059Z ../../../micromamba/envs/tardis/lib/python3.12/site-packages/jupyter_client/connect.py:22
2025-02-17T19:44:21.7748730Z   /home/runner/micromamba/envs/tardis/lib/python3.12/site-packages/jupyter_client/connect.py:22: DeprecationWarning:
2025-02-17T19:44:21.7749230Z   
2025-02-17T19:44:21.7749466Z   Jupyter is migrating its paths to use standard platformdirs
2025-02-17T19:44:21.7749846Z   given by the platformdirs library.  To remove this warning and
2025-02-17T19:44:21.7750241Z   see the appropriate new directories, set the environment variable
2025-02-17T19:44:21.7750763Z   `JUPYTER_PLATFORM_DIRS=1` and then run `jupyter --paths`.
2025-02-17T19:44:21.7751140Z   The use of platformdirs will be the default in `jupyter_core` v6
2025-02-17T19:44:21.7751376Z 
2025-02-17T19:44:21.7751564Z -- Docs: https://docs.pytest.org/en/stable/how-to/capture-warnings.html
2025-02-17T19:44:21.7751838Z 
2025-02-17T19:44:21.7752002Z ---------- coverage: platform linux, python 3.12.4-final-0 -----------
2025-02-17T19:44:21.7752360Z Coverage HTML written to dir coverage_html_report
2025-02-17T19:44:21.7752662Z Coverage XML written to file coverage.xml
2025-02-17T19:44:21.7752841Z 
2025-02-17T19:44:21.7752970Z =========================== short test summary info ============================
2025-02-17T19:44:21.7758548Z ERROR tardis/transport/montecarlo/estimators/tests/test_continuum_property_solver.py::test_continuum_estimators - tables.exceptions.HDF5ExtError: HDF5 error back trace
2025-02-17T19:44:21.7759204Z 
2025-02-17T19:44:21.7759319Z   File "H5F.c", line 836, in H5Fopen
2025-02-17T19:44:21.7759594Z     unable to synchronously open file
2025-02-17T19:44:21.7759878Z   File "H5F.c", line 796, in H5F__open_api_common
2025-02-17T19:44:21.7760189Z     unable to open file
2025-02-17T19:44:21.7760437Z   File "H5VLcallback.c", line 3863, in H5VL_file_open
2025-02-17T19:44:21.7760705Z     open failed
2025-02-17T19:44:21.7760927Z   File "H5VLcallback.c", line 3675, in H5VL__file_open
2025-02-17T19:44:21.7761190Z     open failed
2025-02-17T19:44:21.7761438Z   File "H5VLnative_file.c", line 128, in H5VL__native_file_open
2025-02-17T19:44:21.7761925Z     unable to open file
2025-02-17T19:44:21.7762144Z   File "H5Fint.c", line 2018, in H5F_open
2025-02-17T19:44:21.7762399Z     unable to read superblock
2025-02-17T19:44:21.7762649Z   File "H5Fsuper.c", line 392, in H5F__super_read
2025-02-17T19:44:21.7762922Z     file signature not found
2025-02-17T19:44:21.7763069Z 
2025-02-17T19:44:21.7763155Z End of HDF5 error back trace
2025-02-17T19:44:21.7763301Z 
2025-02-17T19:44:21.7763856Z Unable to open/create file '/home/runner/work/tardis/tardis/tardis-regression-data/atom_data/nlte_atom_data/TestNLTE_He_Ti.h5'
2025-02-17T19:44:21.7764760Z ERROR tardis/transport/montecarlo/tests/test_continuum.py::test_montecarlo_continuum - tables.exceptions.HDF5ExtError: HDF5 error back trace
2025-02-17T19:44:21.7765271Z 
2025-02-17T19:44:21.7765362Z   File "H5F.c", line 836, in H5Fopen
2025-02-17T19:44:21.7765611Z     unable to synchronously open file
2025-02-17T19:44:21.7765884Z   File "H5F.c", line 796, in H5F__open_api_common
2025-02-17T19:44:21.7766154Z     unable to open file
2025-02-17T19:44:21.7766392Z   File "H5VLcallback.c", line 3863, in H5VL_file_open
2025-02-17T19:44:21.7766657Z     open failed
2025-02-17T19:44:21.7766879Z   File "H5VLcallback.c", line 3675, in H5VL__file_open
2025-02-17T19:44:21.7767144Z     open failed
2025-02-17T19:44:21.7767392Z   File "H5VLnative_file.c", line 128, in H5VL__native_file_open
2025-02-17T19:44:21.7767690Z     unable to open file
2025-02-17T19:44:21.7767906Z   File "H5Fint.c", line 2018, in H5F_open
2025-02-17T19:44:21.7768157Z     unable to read superblock
2025-02-17T19:44:21.7768409Z   File "H5Fsuper.c", line 392, in H5F__super_read
2025-02-17T19:44:21.7768674Z     file signature not found
2025-02-17T19:44:21.7768814Z 
2025-02-17T19:44:21.7768897Z End of HDF5 error back trace
2025-02-17T19:44:21.7769032Z 
2025-02-17T19:44:21.7769407Z Unable to open/create file '/home/runner/work/tardis/tardis/tardis-regression-data/atom_data/nlte_atom_data/TestNLTE_He_Ti.h5'
2025-02-17T19:44:21.7770010Z =============== 1794 deselected, 3 warnings, 2 errors in 10.63s ================
2025-02-17T19:44:22.4153509Z ##[error]Process completed with exit code 1.
