2025-01-10T11:38:20.5035771Z ##[group]Run pytest tardis --tardis-regression-data=/home/runner/work/tardis/tardis/tardis-regression-data --cov=tardis --cov-report=xml --cov-report=html --cov-append -m " continuum"
2025-01-10T11:38:20.5038228Z [36;1mpytest tardis --tardis-regression-data=/home/runner/work/tardis/tardis/tardis-regression-data --cov=tardis --cov-report=xml --cov-report=html --cov-append -m " continuum"[0m
2025-01-10T11:38:20.5073665Z shell: /usr/bin/bash -l {0}
2025-01-10T11:38:20.5073902Z env:
2025-01-10T11:38:20.5074062Z   CACHE_NUMBER: 0
2025-01-10T11:38:20.5074697Z   PYTEST_FLAGS: --tardis-regression-data=/home/runner/work/tardis/tardis/tardis-regression-data --cov=tardis --cov-report=xml --cov-report=html --cov-append
2025-01-10T11:38:20.5075363Z   CODECOV_TOKEN: 
2025-01-10T11:38:20.5075565Z   MAMBA_ROOT_PREFIX: /home/runner/micromamba
2025-01-10T11:38:20.5075855Z   MAMBA_EXE: /home/runner/micromamba-bin/micromamba
2025-01-10T11:38:20.5076203Z   CONDARC: /home/runner/work/_temp/setup-micromamba/.condarc
2025-01-10T11:38:20.5076551Z ##[endgroup]
2025-01-10T11:38:27.3731132Z 
2025-01-10T11:38:27.3731795Z Iterations:                                                                                0/? [00:00<?, ?it/s]
2025-01-10T11:38:27.3732559Z 
2025-01-10T11:38:27.3740786Z Packets:                                                                                   0/? [00:00<?, ?it/s][AImportError while loading conftest '/home/runner/work/tardis/tardis/tardis/conftest.py'.
2025-01-10T11:38:27.6150031Z tardis/conftest.py:11: in <module>
2025-01-10T11:38:27.6150774Z     from tardis.simulation import Simulation
2025-01-10T11:38:27.6151435Z tardis/simulation/__init__.py:5: in <module>
2025-01-10T11:38:27.6152396Z     from tardis.simulation.base import Simulation
2025-01-10T11:38:27.6153088Z tardis/simulation/base.py:14: in <module>
2025-01-10T11:38:27.6153926Z     from tardis.io.model.parse_simulation_state import (
2025-01-10T11:38:27.6155099Z tardis/io/model/parse_simulation_state.py:4: in <module>
2025-01-10T11:38:27.6156013Z     from tardis.model import SimulationState
2025-01-10T11:38:27.6156499Z tardis/model/__init__.py:9: in <module>
2025-01-10T11:38:27.6156989Z     from tardis.model.base import SimulationState
2025-01-10T11:38:27.6157489Z tardis/model/base.py:10: in <module>
2025-01-10T11:38:27.6158062Z     from tardis.io.model.parse_composition_configuration import (
2025-01-10T11:38:27.6158801Z tardis/io/model/parse_composition_configuration.py:1: in <module>
2025-01-10T11:38:27.6159502Z     from tardis.io.model.parse_density_configuration import (
2025-01-10T11:38:27.6160184Z tardis/io/model/parse_density_configuration.py:11: in <module>
2025-01-10T11:38:27.6160870Z     from tardis.io.model.parse_geometry_configuration import (
2025-01-10T11:38:27.6161542Z tardis/io/model/parse_geometry_configuration.py:5: in <module>
2025-01-10T11:38:27.6162527Z     from tardis.io.model.readers.base import read_density_file
2025-01-10T11:38:27.6163138Z tardis/io/model/readers/base.py:9: in <module>
2025-01-10T11:38:27.6163726Z     from tardis.io.model.readers.generic_readers import (
2025-01-10T11:38:27.6164372Z tardis/io/model/readers/generic_readers.py:6: in <module>
2025-01-10T11:38:27.6164918Z     from numpy import recfromtxt
2025-01-10T11:38:27.6166183Z E   ImportError: cannot import name 'recfromtxt' from 'numpy' (/home/runner/micromamba/envs/tardis/lib/python3.12/site-packages/numpy/__init__.py). Did you mean: 'genfromtxt'?
2025-01-10T11:38:28.0166972Z ##[error]Process completed with exit code 4.
